<?xml version="1.0"?>
<robot name="medibot">

  <link name="base_link">
    <visual>
      <origin xyz="0 0 0.05" rpy="0 0 0"/> <geometry>
        <cylinder length="0.1" radius="0.15"/>
      </geometry>
      <material name="blue">
        <color rgba="0.0 0.0 1.0 1.0"/>
      </material>
    </visual>
    <collision>
      <origin xyz="0 0 0.05" rpy="0 0 0"/>
      <geometry>
        <cylinder length="0.1" radius="0.15"/>
      </geometry>
    </collision>
    <inertial>
      <origin xyz="0 0 0.05" rpy="0 0 0"/>
      <mass value="1.0"/>
      <inertia ixx="0.01" ixy="0" ixz="0" iyy="0.01" iyz="0" izz="0.01"/>
    </inertial>
  </link>

  <link name="left_wheel_link">
    <visual>
      <origin xyz="0 0 0" rpy="1.5707 0 0"/> <geometry>
        <cylinder length="0.04" radius="0.05"/>
      </geometry>
      <material name="black">
        <color rgba="0.0 0.0 0.0 1.0"/>
      </material>
    </visual>
    <collision>
      <origin xyz="0 0 0" rpy="1.5707 0 0"/>
      <geometry>
        <cylinder length="0.04" radius="0.05"/>
      </geometry>
    </collision>
    <inertial>
      <origin xyz="0 0 0" rpy="1.5707 0 0"/>
      <mass value="0.1"/>
      <inertia ixx="0.001" ixy="0" ixz="0" iyy="0.001" iyz="0" izz="0.001"/>
    </inertial>
  </link>

  <link name="right_wheel_link">
    <visual>
      <origin xyz="0 0 0" rpy="1.5707 0 0"/> <geometry>
        <cylinder length="0.04" radius="0.05"/>
      </geometry>
      <material name="black"/> </visual>
    <collision>
      <origin xyz="0 0 0" rpy="1.5707 0 0"/>
      <geometry>
        <cylinder length="0.04" radius="0.05"/>
      </geo_msgs>
    </collision>
    <inertial>
      <origin xyz="0 0 0" rpy="1.5707 0 0"/>
      <mass value="0.1"/>
      <inertia ixx="0.001" ixy="0" ixz="0" iyy="0.001" iyz="0" izz="0.001"/>
    </inertial>
  </link>

  <link name="world"/>
  <joint name="world_joint" type="fixed">
    <parent link="world"/>
    <child link="base_link"/>
    <origin xyz="0 0 0.05"/> </joint>

  <joint name="left_wheel_joint" type="continuous">
    <parent link="base_link"/>
    <child link="left_wheel_link"/>
    <origin xyz="0 0.17 0.0" rpy="0 0 0"/> <axis xyz="0 1 0"/> </joint>
  
  <joint name="right_wheel_joint" type="continuous">
    <parent link="base_link"/>
    <child link="right_wheel_link"/>
    <origin xyz="0 -0.17 0.0" rpy="0 0 0"/> <axis xyz="0 1 0"/> </joint>

  <gazebo reference="base_link">
    <material>Gazebo/Blue</material>
  </gazebo>
  <gazebo reference="left_wheel_link">
    <material>Gazebo/Black</material>
  </gazebo>
  <gazebo reference="right_wheel_link">
    <material>Gazebo/Black</material>
  </gazebo>
<geometry>
        <cylinder length="0.04" radius="0.05"/>
      </geo_msgs> </collision>
      </geometry>
</robot>
