<?xml version="1.0"?>
<robot name="medibot">

  <!-- BASE -->
  <link name="base_link">
    <visual>
      <geometry>
        <box size="0.5 0.3 0.2"/>
      </geometry>
    </visual>
  </link>

  <!-- LEFT WHEEL -->
  <link name="left_wheel">
    <visual>
      <geometry>
        <cylinder radius="0.1" length="0.05"/>
      </geometry>
    </visual>
  </link>

  <!-- RIGHT WHEEL -->
  <link name="right_wheel">
    <visual>
      <geometry>
        <cylinder radius="0.1" length="0.05"/>
      </geometry>
    </visual>
  </link>

  <!-- WHEEL JOINTS -->
  <joint name="left_wheel_joint" type="continuous">
    <parent link="base_link"/>
    <child link="left_wheel"/>
    <origin xyz="0 0.2 0"/>
    <axis xyz="0 1 0"/>
  </joint>

  <joint name="right_wheel_joint" type="continuous">
    <parent link="base_link"/>
    <child link="right_wheel"/>
    <origin xyz="0 -0.2 0"/>
    <axis xyz="0 1 0"/>
  </joint>

  <!-- LIDAR -->
  <link name="laser_link"/>

  <joint name="laser_joint" type="fixed">
    <parent link="base_link"/>
    <child link="laser_link"/>
    <origin xyz="0 0 0.25"/>
  </joint>

  <!-- GAZEBO LIDAR SENSOR -->
  <gazebo reference="laser_link">
    <sensor type="ray" name="laser">
      <update_rate>10</update_rate>
      <ray>
        <scan>
          <horizontal>
            <samples>360</samples>
            <min_angle>-3.14</min_angle>
            <max_angle>3.14</max_angle>
          </horizontal>
        </scan>
        <range>
          <min>0.1</min>
          <max>10.0</max>
        </range>
      </ray>

      <plugin name="laser" filename="libgazebo_ros_ray_sensor.so">
        <ros>
          <namespace>/</namespace>
        </ros>
        <topicName>/scan</topicName>
        <frameName>laser_link</frameName>
      </plugin>
    </sensor>
  </gazebo>

  <!-- DIFFERENTIAL DRIVE -->
  <gazebo>
    <plugin name="diff_drive" filename="libgazebo_ros_diff_drive.so">

      <left_joint>left_wheel_joint</left_joint>
      <right_joint>right_wheel_joint</right_joint>

      <wheel_separation>0.4</wheel_separation>
      <wheel_radius>0.1</wheel_radius>

      <publish_odom>true</publish_odom>
      <publish_odom_tf>true</publish_odom_tf>

      <odometry_topic>odom</odometry_topic>
      <odometry_frame>odom</odometry_frame>
      <robot_base_frame>base_link</robot_base_frame>

    </plugin>
  </gazebo>

</robot>
